Workbook

Sheet Puntos
A1: NOMBRE | B1: IMPRESORA | C1: DESCRIPCION | D1: UBICACIÓN | E1: REP | H1: FC | I1: Firma | J1: ESTADO
A2: MI FARMACIA ARANZAZU CALDAS | C2: HP Laser MFP 135w | D2: Punto | E2: 1 | I2: OK | K2: ok | L2: 2
A3: MI FARMACIA GUAJIRA | C3: HP Laser MFP 135w | D3: Punto | E3: 0 | I3: ok
A4: MI FARMACIA CORINTO | C4: HP LaserJet Pro P1102 | D4: Punto | E4: 1 | I4: OK | K4: ok | L4: 1
A5: MI FARMACIA QUIMBAYA | C5: Samsung M2070w | D5: Punto | I5: mantenimiento / tiene ahora una hp 1102 de reemplazo | L5: 1
A6: MI FARMACIA LA VIRIGINA 2 | C6: HP LaserJet Pro P1102 | D6: Punto | E6: 1 | I6: OK | K6: ok | L6: 1
A7: MI FARMCACIA CAICEDONIA | C7: HP LaserJet Pro P1102 | D7: Punto | I7: OK | L7: 1
A8: HOSPITALARIA | C8: Epson L3110 | D8: Punto | I8: OK
A9: CIPRES | C9: Epson L210 | D9: Punto | I9: OK
A10: ZARAGOZA | C10: Epson L3110 | D10: Punto | I10: OK
A11: SAN JOAQUIN | C11: Epson L210 | D11: Punto | I11: OK
A12: FARMACIA HOSPITAL CARMONA | C12: HP LaserJet Pro P1102 | D12: Punto | I12: OK
A13: MI FARMCACIA TUMACO | C13: HP LaserJet Pro M1212nf | D13: Punto | E13: 1 | I13: OK | L13: 2
A14: MI FARMCACIA MOCOA | C14: HP LaserJet Pro 1536 | D14: Punto | I14: OK
A15: MI FARMCACIA MIRANDA | C15: Epson L3110 | D15: Punto | I15: OK | K15: OK
A16: MI FARMACIA LA UNION | C16: Epson L210 | D16: Punto | I16: OK | K16: OK
A17: MI FARMACIA APIA | C17: HP LaserJet Pro 1536 | D17: Punto | I17: OK
A18: MI FARMACIA ANSERMA NUEVO | C18: HP LaserJet Pro P1102 | D18: Punto | I18: OK | L18: 1
A19: MI FARMACIA ANSERMA NUEVO | C19: Epson L210 | D19: Punto | I19: OK
A20: MI FARMCACIA PASTO

Sheet Base
A1: COD | B1: NOMBRE | C1: DESCRIPCION | D1: ARTICULO
A2: 1 | B2: MI FARMACIA JAMUNDI | C2: COMPUTADOR | D2: TONER | E2: 6
A3: 1 | B3: MI FARMACIA JAMUNDI | C3: COMPUTADOR | D3: TONER
A4: 2 | B4: MI FARMACIA BARBACOA | C4: COMPUTADOR | D4: EQUIPO
A5: 2 | B5: MI FARMACIA BARBACOA | C5: COMPUTADOR | D5: EQUIPO
A6: 3 | B6: MI FARMACIA TUMACO | C6: COMPUTADOR | D6: EQUIPO
A7: 3 | B7: MI FARMACIA TUMACO | C7: COMPUTADOR | D7: EQUIPO | H7: MI FARMACIA BARBACOA
A8: 4 | B8: HOSPITALARIA | C8: COMPUTADOR | D8: EQUIPO | H8: MI FARMACIA TUMACO
A9: 4 | B9: HOSPITALARIA | C9: COMPUTADOR | D9: EQUIPO | E9: 5 | F9: ok | H9: MI FARMACIA HOSPITALARIA
A10: 5 | B10: MI FARMACIA NARIÑO | C10: COMPUTADOR | D10: EQUIPO | F10: ok | H10: MI FARMACIA NARIÑO
A11: 5 | B11: MI FARMACIA NARIÑO | C11: COMPUTADOR | D11: EQUIPO | F11: ok | H11: MI FARMACIA SEVILLA
A12: 6 | B12: MI FARMACIA SEVILLA | C12: COMPUTADOR | D12: EQUIPO | F12: ok
A13: 6 | B13: MI FARMACIA SEVILLA | C13: COMPUTADOR | D13: EQUIPO | F13: ok
A14: 13 | C14: COMPUTADOR | D14: EQUIPO | E14: 8 | F14: ok
A15: 14 | C15: COMPUTADOR | D15: TONER
A16: 15 | C16: HP LaserJet Pro P1102 | D16: TONER
A17: 16 | C17: HP LaserJet Pro P1102 | D17: TONER
A18: 17 | C18: HP LaserJet Pro P1102 | D18: TONER
A19: 18 | C19: HP LaserJet Pro P1102 | D19: TONER
A20: 19 | C20: HP LaserJet Pro P1102 | D20: TONER
A21: 20 | C21: HP LaserJet Pro P1102 | D21: TONER
A22: 21 | C22: HP LaserJet Pro P1102 | D22: TONER
A23: 22 | C23: Samsung M2070w | D23: TONER

Sheet Rotulo
D1: FORMATO PARA DESPACHO | M1: =+TODAY() -> 46168
A4: FECHA | C4: DIA | F4: MES | I4: AÑO
C5: =+IF($M$1=0,"Sin Selección",DAY($M$1)) -> 26 | F5: =IF($M$1=0,"Sin Selección",MONTH($M$1)) -> 5 | I5: =IF($M$1=0,"Sin Selección",YEAR($M$1)) -> 2026
A7: DESTINO | C7: =+IF(M7=0,"Sin Selección",VLOOKUP(M7,Base!$A$2:$B$23,2,0)) -> MI FARMACIA JAMUNDI | M7: 1
A9: REMITE | C9: FELIPE VILLEGAS / DPTO SISTEMAS
A11: CAJAS | C11: 1 | E11: =IF(C11=0,"Sin Selección",C11) -> 1 | G11: OBSERVACION
G12: =+IF(M7=0,"Sin Selección",VLOOKUP(M7,Base!$A$2:$D$23,4,0)) -> TONER
D25: FORMATO PARA DESPACHO
A28: FECHA | C28: DIA | F28: MES | I28: AÑO
C29: =+IF($M$1=0,"Sin Selección",DAY($M$1)) -> 26 | F29: =IF($M$1=0,"Sin Selección",MONTH($M$1)) -> 5 | I29: =IF($M$1=0,"Sin Selección",YEAR($M$1)) -> 2026
A31: DESTINO | C31: =+IF(M31=0,"Sin Selección",VLOOKUP(M31,Base!$A$2:$B$23,2,0)) -> MI FARMACIA JAMUNDI | M31: 1
A33: REMITE | C33: =+$C$9 -> FELIPE VILLEGAS / DPTO SISTEMAS
A35: CAJAS | C35: 1 | E35: 1 | G35: OBSERVACION
G36: =+IF(M31=0,"Sin Selección",VLOOKUP(M31,Base!$A$2:$D$23,4,0)) -> TONER
D38: FORMATO PARA DESPACHO
A41: FECHA | C41: DIA | F41: MES | I41: AÑO
C42: =+IF($M$1=0,"Sin Selección",DAY($M$1)) -> 26 | F42: 10 | I42: 2023
A44: DESTINO | C44: =+IF(M44=0,"Sin Selección",VLOOKUP(M44,Base!$A$2:$B$23,2,0)) -> MI FARMACIA BARBACOA | M44: 2
A46: REMITE | C46: =+$C$9 -> FELIPE VILLEGAS / DPTO SISTEMAS
A48: CAJAS | C48: 1 | E48: 1 | G48: OBSERVACION
G49: =+IF(M44=0,"Sin Selección",VLOOKUP(M44,Base!$A$2:$D$23,4,0)) -> EQUIPO
D60: FORMATO PARA DESPACHO
A63: FECHA | C63: DIA | F63: MES | I63: AÑO
C64: =+IF($M$1=0,"Sin Selección",DAY($M$1)) -> 26 | F64: 10 | I64: 2023
A66: DESTINO | C66: =+IF(M66=0,"Sin Selección",VLOOKUP(M66,Base!$A$2:$B$23,2,0)) -> MI FARMACIA BARBACOA | M66: 2
A68: REMITE | C68: =+$C$9 -> FELIPE VILLEGAS / DPTO SISTEMAS
A70: CAJAS | C70: 1 | E70: 1 | G70: OBSERVACION
G71: =+IF(M66=0,"Sin Selección",VLOOKUP(M66,Base!$A$2:$D$23,4,0)) -> EQUIPO
D73: FORMATO PARA DESPACHO
A76: FECHA | C76: DIA | F76: MES | I76: AÑO
C77: =+IF($M$1=0,"Sin Selección",DAY($M$1)) -> 26 | F77: 10 | I77: 2023
A79: DESTINO | C79: =+IF(M79=0,"Sin Selección",VLOOKUP(M79,Base!$A$2:$B$23,2,0)) -> MI FARMACIA TUMACO | M79: 3
A81: REMITE | C81: =+$C$9 -> FELIPE VILLEGAS / DPTO SISTEMAS
A83: CAJAS | C83: 1 | E83: 1 | G83: OBSERVACION
G84: =+IF(M79=0,"Sin Selección",VLOOKUP(M79,Base!$A$2:$D$23,4,0)) -> EQUIPO
D95: FORMATO PARA DESPACHO
A98: FECHA | C98: DIA | F98: MES | I98: AÑO
C99: =+IF($M$1=0,"Sin Selección",DAY($M$1)) -> 26 | F99: 10 | I99: 2023
A101: DESTINO | C101: =+IF(M101=0,"Sin Selección",VLOOKUP(M101,Base!$A$2:$B$23,2,0)) -> MI FARMACIA TUMACO | M101: 3
A103: REMITE | C103: =+$C$9 -> FELIPE VILLEGAS / DPTO SISTEMAS
...

Sheet Rotulo (2)
D1: FORMATO PARA DESPACHO | M1: =+TODAY() -> 46168
A4: FECHA | C4: DIA | F4: MES | I4: AÑO
C5: =+IF($M$1=0,"Sin Selección",DAY($M$1)) -> 26 | F5: =IF($M$1=0,"Sin Selección",MONTH($M$1)) -> 5 | I5: =IF($M$1=0,"Sin Selección",YEAR($M$1)) -> 2026
A7: DESTINO | C7: =+IF(M7=0,"Sin Selección",VLOOKUP(M7,Base!$A$2:$B$23,2,0)) -> MI FARMACIA JAMUNDI | M7: 1
A9: REMITE | C9: FELIPE VILLEGAS / DPTO SISTEMAS
A11: CAJAS | C11: 1 | E11: =IF(C11=0,"Sin Selección",C11) -> 1 | G11: OBSERVACION
G12: =+IF(M7=0,"Sin Selección",VLOOKUP(M7,Base!$A$2:$D$23,4,0)) -> TONER
D25: FORMATO PARA DESPACHO
A28: FECHA | C28: DIA | F28: MES | I28: AÑO
C29: =+IF($M$1=0,"Sin Selección",DAY($M$1)) -> 26 | F29: =IF($M$1=0,"Sin Selección",MONTH($M$1)) -> 5 | I29: =IF($M$1=0,"Sin Selección",YEAR($M$1)) -> 2026
A31: DESTINO | C31: =+IF(M31=0,"Sin Selección",VLOOKUP(M31,Base!$A$2:$B$23,2,0)) -> MI FARMACIA JAMUNDI | M31: 1
A33: REMITE | C33: =+$C$9 -> FELIPE VILLEGAS / DPTO SISTEMAS
A35: CAJAS | C35: 1 | E35: 1 | G35: OBSERVACION
G36: =+IF(M31=0,"Sin Selección",VLOOKUP(M31,Base!$A$2:$D$23,4,0)) -> TONER
D38: FORMATO PARA DESPACHO
A41: FECHA | C41: DIA | F41: MES | I41: AÑO
C42: =+IF($M$1=0,"Sin Selección",DAY($M$1)) -> 26 | F42: 10 | I42: 2023
A44: DESTINO | C44: =+IF(M44=0,"Sin Selección",VLOOKUP(M44,Base!$A$2:$B$23,2,0)) -> MI FARMACIA TUMACO | M44: 3
A46: REMITE | C46: =+$C$9 -> FELIPE VILLEGAS / DPTO SISTEMAS
A48: CAJAS | C48: 1 | E48: 1 | G48: OBSERVACION
G49: =+IF(M44=0,"Sin Selección",VLOOKUP(M44,Base!$A$2:$D$23,4,0)) -> EQUIPO
D62: FORMATO PARA DESPACHO
A65: FECHA | C65: DIA | F65: MES | I65: AÑO
C66: =+IF($M$1=0,"Sin Selección",DAY($M$1)) -> 26 | F66: 10 | I66: 2023
A68: DESTINO | C68: =+IF(M68=0,"Sin Selección",VLOOKUP(M68,Base!$A$2:$B$23,2,0)) -> HOSPITALARIA | M68: 4
A70: REMITE | C70: =+$C$9 -> FELIPE VILLEGAS / DPTO SISTEMAS
A72: CAJAS | C72: 1 | E72: 1 | G72: OBSERVACION
G73: =+IF(M68=0,"Sin Selección",VLOOKUP(M68,Base!$A$2:$D$23,4,0)) -> EQUIPO
D75: FORMATO PARA DESPACHO
A78: FECHA | C78: DIA | F78: MES | I78: AÑO
C79: =+IF($M$1=0,"Sin Selección",DAY($M$1)) -> 26 | F79: 10 | I79: 2023
A81: DESTINO | C81: =+IF(M81=0,"Sin Selección",VLOOKUP(M81,Base!$A$2:$B$23,2,0)) -> MI FARMACIA NARIÑO | M81: 5
A83: REMITE | C83: =+$C$9 -> FELIPE VILLEGAS / DPTO SISTEMAS
A85: CAJAS | C85: 1 | E85: 1 | G85: OBSERVACION
G86: =+IF(M81=0,"Sin Selección",VLOOKUP(M81,Base!$A$2:$D$23,4,0)) -> EQUIPO
D99: FORMATO PARA DESPACHO
A102: FECHA | C102: DIA | F102: MES | I102: AÑO
C103: =+IF($M$1=0,"Sin Selección",DAY($M$1)) -> 26 | F103: 10 | I103: 2023
A105: DESTINO | C105: =+IF(M105=0,"Sin Selección",VLOOKUP(M105,Base!$A$2:$B$23,2,0)) -> MI FARMACIA SEVILLA | M105: 6
A107: REMITE | C107: =+$C$9 -> FELIPE VILLEGAS / DPTO SISTEMAS
...

Sheet Hoja2
A1: NOMBRE | B1: IMPRESORA | C1: DESCRIPCION | D1: UBICACIÓN | E1: REPOSICION | F1: Undis
A2: GISELA | C2: HP LaserJet Pro P1102 | D2: Principal
A3: EMPAQUE | C3: HP LaserJet Pro P1102 | D3: Principal
A4: EMPAQUE | C4: HP LaserJet Pro P1102 | D4: Principal
A5: DESPACHO | C5: HP LaserJet Pro P1102 | D5: Principal
A6: RECEPCION | C6: Epson L3110 | D6: Principal
A7: VENTAS | C7: HP LaserJet Pro serie M404-M405 | D7: Principal
A8: VENTAS | C8: HP LaserJet M236sdw | D8: Principal
A9: VENTAS | C9: HP LaserJet Pro P1606dn | D9: Principal
A10: COMPRAS | C10: HP LaserJet Pro M1212nf | D10: Principal
A11: CARTERA | C11: HP LaserJet Pro P1102 | D11: Principal
A12: CONTABILIDAD | C12: HP LaserJet Pro P1102 | D12: Principal
A13: RH | C13: Epson L3210 | D13: Principal

Sheet Hoja5
B1: ARTICULO
B2: CARGADOR
B3: CARGADOR
B4: IMPRESORA
B5: EQUIPO
B6: UPS
B7: MONITOR
B8: TURNERO
B9: TONER
B10: TECLADO
B11: ESCANER
B12: MOUSE
B13: VGA
A137: TVZ TECNOLOGY

Sheet Hoja1
